<?xml version="1.0" encoding="utf-8"?>
<sdf version="1.5">
  <model name="Mildread2015">
    <pose>0 0 -0.0641857999998441 0 0 0</pose>
    <plugin name="clock" filename="libgz_clock.so">
      <topic>/gazebo/frc/time</topic>
    </plugin>
    <link name="Chassis">
      <gravity>1</gravity>
      <self_collide>0</self_collide>
      <pose>0.0380029889506857 -0.00235709265715786 0.398592483781348 1.5707963267949 2.31519275537905E-15 -1.5707963267949</pose>
      <must_be_base_link>1</must_be_base_link>
      <velocity_decay>
        <linear>0</linear>
        <angular>0</angular>
      </velocity_decay>
      <inertial>
        <mass>12.5954657007975</mass>
        <pose>0 0 0 0 0 0</pose>
        <inertia>
          <ixx>4.15538346471795</ixx>
          <ixy>0.0117617887458408</ixy>
          <ixz>0.00608192316874415</ixz>
          <iyy>1.42548615639183</iyy>
          <iyz>0.70356227808634</iyz>
          <izz>4.34412622713074</izz>
        </inertia>
      </inertial>
      <collision name="Chassis_collision">
        <pose>-0.00235709265715695 -0.398592483781348 0.0380029889506856 0 0 0</pose>
        <geometry>
          <mesh>
            <scale>1 1 1</scale>
            <uri>model://Mildread2015/meshes/Chassis_col.STL</uri>
          </mesh>
        </geometry>
        <surface>
          <contact>
            <ode />
          </contact>
          <friction>
            <ode>
              <mu>0.5</mu>
              <mu2>0.5</mu2>
            </ode>
          </friction>
        </surface>
      </collision>
      <visual name="Chassis_visual">
        <pose>-0.00235709265715695 -0.398592483781348 0.0380029889506856 0 0 0</pose>
        <material>
          <ambient>1 0 0 1</ambient>
          <diffuse>1 0 0 1</diffuse>
        </material>
        <geometry>
          <mesh>
            <scale>1 1 1</scale>
            <uri>model://Mildread2015/meshes/Chassis.STL</uri>
          </mesh>
        </geometry>
      </visual>
      <sensor name="LeftChassisUltrasonic" type="sonar">
        <always_on>1</always_on>
        <visualize>1</visualize>
        <pose>-0.317704442657165 -0.230867483781196 -0.276072010994604 0 0 1.5707963267949</pose>
        <sonar>
          <min>0.1</min>
          <max>2</max>
          <radius>0.05</radius>
        </sonar>
      </sensor>
      <sensor name="RightChassisUltrasonic" type="sonar">
        <always_on>1</always_on>
        <visualize>1</visualize>
        <pose>0.312990257342842 -0.230867483781195 -0.276072009207477 0 0 1.5707963267949</pose>
        <sonar>
          <min>0.1</min>
          <max>2</max>
          <radius>0.05</radius>
        </sonar>
      </sensor>
    </link>
    <link name="LF">
      <gravity>1</gravity>
      <self_collide>0</self_collide>
      <pose>0.24500840000005 0.312470799999999 -0.0133857999997411 1.5707963267949 2.31519275537905E-15 -1.5707963267949</pose>
      <must_be_base_link>0</must_be_base_link>
      <velocity_decay>
        <linear>0</linear>
        <angular>0</angular>
      </velocity_decay>
      <inertial>
        <mass>0.277999991332051</mass>
        <pose>0 0 0 0 0 0</pose>
        <inertia>
          <ixx>0.000358708948815572</ixx>
          <ixy>3.51980482743536E-19</ixy>
          <ixz>5.39723461724909E-19</ixz>
          <iyy>0.000206593935208469</iyy>
          <iyz>1.2620663450194E-33</iyz>
          <izz>0.000206593935208469</izz>
        </inertia>
      </inertial>
      <collision name="LF_collision">
        <pose>0.312470799999999 0.0133857999997417 0.24500840000005 0 0 0</pose>
        <geometry>
          <mesh>
            <scale>1 1 1</scale>
            <uri>model://Mildread2015/meshes/LF_col.STL</uri>
          </mesh>
        </geometry>
        <surface>
          <contact>
            <ode />
          </contact>
          <friction>
            <ode>
              <mu>5</mu>
              <mu2>0</mu2>
              <fdir1>1 0 0</fdir1>
            </ode>
          </friction>
        </surface>
      </collision>
      <visual name="LF_visual">
        <pose>0.312470799999999 0.0133857999997417 0.24500840000005 0 0 0</pose>
        <material>
          <ambient>1 0 0 1</ambient>
          <diffuse>1 0 0 1</diffuse>
        </material>
        <geometry>
          <mesh>
            <scale>1 1 1</scale>
            <uri>model://Mildread2015/meshes/LF.STL</uri>
          </mesh>
        </geometry>
      </visual>
    </link>
    <joint name="Chassis-LF" type="revolute">
      <parent>Chassis</parent>
      <child>LF</child>
      <pose>-3.33066907387547E-16 1.73472347597681E-18 2.77555756156289E-17 0 0 0</pose>
      <axis>
        <xyz>-1 2.32712977238067E-15 -3.23774577026876E-15</xyz>
        <dynamics>
          <damping>0.1</damping>
          <friction>2</friction>
        </dynamics>
        <limit>
          <effort>5</effort>
        </limit>
      </axis>
    </joint>
    <link name="LR">
      <gravity>1</gravity>
      <self_collide>0</self_collide>
      <pose>-0.245008399999999 0.3124708 -0.013385799999843 1.5707963267949 2.31519275537905E-15 -1.5707963267949</pose>
      <must_be_base_link>0</must_be_base_link>
      <velocity_decay>
        <linear>0</linear>
        <angular>0</angular>
      </velocity_decay>
      <inertial>
        <mass>0.277999991332051</mass>
        <pose>0 0 0 0 0 0</pose>
        <inertia>
          <ixx>0.000358708948815572</ixx>
          <ixy>4.98948926069486E-19</ixy>
          <ixz>1.30103361900948E-19</ixz>
          <iyy>0.000206593935208469</iyy>
          <iyz>3.58837037774812E-20</iyz>
          <izz>0.000206593935208469</izz>
        </inertia>
      </inertial>
      <collision name="LR_collision">
        <pose>0.3124708 0.0133857999998438 -0.245008399999999 0 0 0</pose>
        <geometry>
          <mesh>
            <scale>1 1 1</scale>
            <uri>model://Mildread2015/meshes/LR_col.STL</uri>
          </mesh>
        </geometry>
        <surface>
          <contact>
            <ode />
          </contact>
          <friction>
            <ode>
              <mu>5</mu>
              <mu2>0</mu2>
              <fdir1>1 0 0</fdir1>
            </ode>
          </friction>
        </surface>
      </collision>
      <visual name="LR_visual">
        <pose>0.3124708 0.0133857999998438 -0.245008399999999 0 0 0</pose>
        <material>
          <ambient>1 0 0 1</ambient>
          <diffuse>1 0 0 1</diffuse>
        </material>
        <geometry>
          <mesh>
            <scale>1 1 1</scale>
            <uri>model://Mildread2015/meshes/LR.STL</uri>
          </mesh>
        </geometry>
      </visual>
    </link>
    <joint name="Chassis-LR" type="revolute">
      <parent>Chassis</parent>
      <child>LR</child>
      <pose>-3.33066907387547E-16 1.73472347597681E-18 -2.77555756156289E-17 0 0 0</pose>
      <axis>
        <xyz>-1 -2.97391742380892E-15 -6.76391872497219E-16</xyz>
        <dynamics>
          <damping>0.1</damping>
          <friction>2</friction>
        </dynamics>
        <limit>
          <effort>5</effort>
        </limit>
      </axis>
    </joint>
    <link name="RF">
      <gravity>1</gravity>
      <self_collide>0</self_collide>
      <pose>0.245008400000001 -0.312470799999998 -0.0133857999998441 1.5707963267949 2.31519275537905E-15 -1.5707963267949</pose>
      <must_be_base_link>0</must_be_base_link>
      <velocity_decay>
        <linear>0</linear>
        <angular>0</angular>
      </velocity_decay>
      <inertial>
        <mass>0.277999991332051</mass>
        <pose>0 0 0 0 0 0</pose>
        <inertia>
          <ixx>0.000358708948815572</ixx>
          <ixy>3.51980482743536E-19</ixy>
          <ixz>5.35850827090062E-19</ixz>
          <iyy>0.000206593935208469</iyy>
          <iyz>1.25520480510115E-33</iyz>
          <izz>0.000206593935208469</izz>
        </inertia>
      </inertial>
      <collision name="RF_collision">
        <pose>-0.312470799999999 0.0133857999998434 0.245008400000001 0 0 0</pose>
        <geometry>
          <mesh>
            <scale>1 1 1</scale>
            <uri>model://Mildread2015/meshes/RF_col.STL</uri>
          </mesh>
        </geometry>
        <surface>
          <contact>
            <ode />
          </contact>
          <friction>
            <ode>
              <mu>5</mu>
              <mu2>0</mu2>
              <fdir1>1 0 0</fdir1>
            </ode>
          </friction>
        </surface>
      </collision>
      <visual name="RF_visual">
        <pose>-0.312470799999999 0.0133857999998434 0.245008400000001 0 0 0</pose>
        <material>
          <ambient>1 0 0 1</ambient>
          <diffuse>1 0 0 1</diffuse>
        </material>
        <geometry>
          <mesh>
            <scale>1 1 1</scale>
            <uri>model://Mildread2015/meshes/RF.STL</uri>
          </mesh>
        </geometry>
      </visual>
    </link>
    <joint name="Chassis-RF" type="revolute">
      <parent>Chassis</parent>
      <child>RF</child>
      <pose>3.88578058618805E-16 1.73472347597681E-18 2.77555756156289E-17 0 0 0</pose>
      <axis>
        <xyz>-1 -2.32712977238067E-15 -3.23774577026876E-15</xyz>
        <dynamics>
          <damping>0.1</damping>
          <friction>2</friction>
        </dynamics>
        <limit>
          <effort>5</effort>
        </limit>
      </axis>
    </joint>
    <link name="RR">
      <gravity>1</gravity>
      <self_collide>0</self_collide>
      <pose>-0.245008399999779 -0.312470799999996 -0.0133858000003571 1.5707963267949 2.31519275537905E-15 -1.5707963267949</pose>
      <must_be_base_link>0</must_be_base_link>
      <velocity_decay>
        <linear>0</linear>
        <angular>0</angular>
      </velocity_decay>
      <inertial>
        <mass>0.277999991332051</mass>
        <pose>0 0 0 0 0 0</pose>
        <inertia>
          <ixx>0.000358708948815572</ixx>
          <ixy>3.54572681175279E-19</ixy>
          <ixz>5.26697098619803E-19</ixz>
          <iyy>0.000206593935208469</iyy>
          <iyz>3.10429104839227E-20</iyz>
          <izz>0.000206593935208469</izz>
        </inertia>
      </inertial>
      <collision name="RR_collision">
        <pose>-0.312470799999996 0.0133858000003564 -0.245008399999779 0 0 0</pose>
        <geometry>
          <mesh>
            <scale>1 1 1</scale>
            <uri>model://Mildread2015/meshes/RR_col.STL</uri>
          </mesh>
        </geometry>
        <surface>
          <contact>
            <ode />
          </contact>
          <friction>
            <ode>
              <mu>5</mu>
              <mu2>0</mu2>
              <fdir1>1 0 0</fdir1>
            </ode>
          </friction>
        </surface>
      </collision>
      <visual name="RR_visual">
        <pose>-0.312470799999996 0.0133858000003564 -0.245008399999779 0 0 0</pose>
        <material>
          <ambient>1 0 0 1</ambient>
          <diffuse>1 0 0 1</diffuse>
        </material>
        <geometry>
          <mesh>
            <scale>1 1 1</scale>
            <uri>model://Mildread2015/meshes/RR.STL</uri>
          </mesh>
        </geometry>
      </visual>
    </link>
    <joint name="Chassis-RR" type="revolute">
      <parent>Chassis</parent>
      <child>RR</child>
      <pose>0 0 -5.55111512312578E-17 0 0 0</pose>
      <axis>
        <xyz>-1 -2.11353636658577E-15 -3.32982886807258E-15</xyz>
        <dynamics>
          <damping>0.1</damping>
          <friction>2</friction>
        </dynamics>
        <limit>
          <effort>5</effort>
        </limit>
      </axis>
    </joint>
    <link name="ElevatorCarriage">
      <gravity>1</gravity>
      <self_collide>0</self_collide>
      <pose>0.15935450086794 -7.68943604643712E-14 1.0760994134063 1.5707963267949 2.31519275537905E-15 -1.5707963267949</pose>
      <must_be_base_link>0</must_be_base_link>
      <velocity_decay>
        <linear>0</linear>
        <angular>0</angular>
      </velocity_decay>
      <inertial>
        <mass>0.740046848703826</mass>
        <pose>0 0 0 0 0 0</pose>
        <inertia>
          <ixx>0.0188803339424567</ixx>
          <ixy>1.76073619660017E-14</ixy>
          <ixz>3.23016207965515E-11</ixz>
          <iyy>0.0526417729904565</iyy>
          <iyz>1.33572544372424E-05</iyz>
          <izz>0.0343024306317156</izz>
        </inertia>
      </inertial>
      <collision name="ElevatorCarriage_collision">
        <pose>-7.44383667055735E-14 -1.0760994134063 0.159354500867939 0 0 0</pose>
        <geometry>
          <mesh>
            <scale>1 1 1</scale>
            <uri>model://Mildread2015/meshes/ElevatorCarriage_col.STL</uri>
          </mesh>
        </geometry>
        <surface>
          <contact>
            <ode />
          </contact>
          <friction>
            <ode>
              <mu>0.1</mu>
              <mu2>0.1</mu2>
            </ode>
          </friction>
        </surface>
      </collision>
      <visual name="ElevatorCarriage_visual">
        <pose>-7.44383667055735E-14 -1.0760994134063 0.159354500867939 0 0 0</pose>
        <material>
          <ambient>1 0 0 1</ambient>
          <diffuse>1 0 0 1</diffuse>
        </material>
        <geometry>
          <mesh>
            <scale>1 1 1</scale>
            <uri>model://Mildread2015/meshes/ElevatorCarriage.STL</uri>
          </mesh>
        </geometry>
      </visual>
    </link>
    <joint name="Chassis-ElevatorCarriage" type="prismatic">
      <parent>Chassis</parent>
      <child>ElevatorCarriage</child>
      <pose>-0.298450000000081 4.44089209850063E-16 -0.103058004312019 0 0 0</pose>
      <axis>
        <xyz>-6.14372614900409E-31 1 3.96625982688355E-15</xyz>
        <dynamics>
          <damping>0.1</damping>
          <friction>1</friction>
        </dynamics>
        <limit>
          <upper>0.237049416715823</upper>
          <lower>-0.940050223068703</lower>
          <effort>10</effort>
        </limit>
      </axis>
    </joint>
    <plugin name="Left_Chassis_rangefinder" filename="libgz_rangefinder.so">
      <topic>/gazebo/frc/simulator/analog/1</topic>
      <sensor>LeftChassisUltrasonic</sensor>
    </plugin>
    <plugin name="Right_Chassis_rangefinder" filename="libgz_rangefinder.so">
      <topic>/gazebo/frc/simulator/analog/2</topic>
      <sensor>RightChassisUltrasonic</sensor>
    </plugin>
    <plugin name="Chassis_gyro" filename="libgz_gyro.so">
      <link>Chassis</link>
      <topic>/gazebo/frc/simulator/analog/0</topic>
      <units>degrees</units>
      <axis>yaw</axis>
    </plugin>
    <plugin name="Chassis-LF_motor" filename="libgz_dc_motor.so">
      <joint>Chassis-LF</joint>
      <topic>/gazebo/frc/simulator/pwm/1</topic>
      <multiplier>15</multiplier>
    </plugin>
    <plugin name="Chassis-LR_motor" filename="libgz_dc_motor.so">
      <joint>Chassis-LR</joint>
      <topic>/gazebo/frc/simulator/pwm/1</topic>
      <multiplier>15</multiplier>
    </plugin>
    <plugin name="Chassis-RF_motor" filename="libgz_dc_motor.so">
      <joint>Chassis-RF</joint>
      <topic>/gazebo/frc/simulator/pwm/2</topic>
      <multiplier>15</multiplier>
    </plugin>
    <plugin name="Chassis-RR_motor" filename="libgz_dc_motor.so">
      <joint>Chassis-RR</joint>
      <topic>/gazebo/frc/simulator/pwm/2</topic>
      <multiplier>15</multiplier>
    </plugin>
    <plugin name="Chassis-ElevatorCarriage_motor" filename="libgz_dc_motor.so">
      <joint>Chassis-ElevatorCarriage</joint>
      <topic>/gazebo/frc/simulator/pwm/3</topic>
      <multiplier>15</multiplier>
    </plugin>
    <plugin name="Chassis-ElevatorCarriage_intlimit" filename="libgz_limit_switch.so">
      <joint>Chassis-ElevatorCarriage</joint>
      <topic>/gazebo/frc/simulator/dio/0</topic>
      <type>internal</type>
      <units>degrees</units>
      <min>0</min>
      <max>0.237</max>
    </plugin>
    <plugin name="Chassis-ElevatorCarriage_intlimit" filename="libgz_limit_switch.so">
      <joint>Chassis-ElevatorCarriage</joint>
      <topic>/gazebo/frc/simulator/dio/1</topic>
      <type>internal</type>
      <units>degrees</units>
      <min>-0.94</min>
      <max>0</max>
    </plugin>
  </model>
</sdf>
